2020-08-14 11:46:08,480 ERROR: Exception on /user/bruce [GET] [in /home/leeolivier/.local/lib/python3.8/site-packages/flask/app.py:1891]
Traceback (most recent call last):
  File "/home/leeolivier/.local/lib/python3.8/site-packages/flask/app.py", line 2447, in wsgi_app
    response = self.full_dispatch_request()
  File "/home/leeolivier/.local/lib/python3.8/site-packages/flask/app.py", line 1952, in full_dispatch_request
    rv = self.handle_user_exception(e)
  File "/home/leeolivier/.local/lib/python3.8/site-packages/flask/app.py", line 1821, in handle_user_exception
    reraise(exc_type, exc_value, tb)
  File "/home/leeolivier/.local/lib/python3.8/site-packages/flask/_compat.py", line 39, in reraise
    raise value
  File "/home/leeolivier/.local/lib/python3.8/site-packages/flask/app.py", line 1950, in full_dispatch_request
    rv = self.dispatch_request()
  File "/home/leeolivier/.local/lib/python3.8/site-packages/flask/app.py", line 1936, in dispatch_request
    return self.view_functions[rule.endpoint](**req.view_args)
  File "/home/leeolivier/.local/lib/python3.8/site-packages/flask_login/utils.py", line 272, in decorated_view
    return func(*args, **kwargs)
  File "/home/leeolivier/bitcube/venv/app/routes.py", line 122, in user
    name = User.query.filter_by(name=name).first_or_404()
UnboundLocalError: local variable 'name' referenced before assignment
2020-08-14 11:46:08,646 ERROR: Exception on /user/bruce [GET] [in /home/leeolivier/.local/lib/python3.8/site-packages/flask/app.py:1891]
Traceback (most recent call last):
  File "/home/leeolivier/.local/lib/python3.8/site-packages/flask/app.py", line 2447, in wsgi_app
    response = self.full_dispatch_request()
  File "/home/leeolivier/.local/lib/python3.8/site-packages/flask/app.py", line 1952, in full_dispatch_request
    rv = self.handle_user_exception(e)
  File "/home/leeolivier/.local/lib/python3.8/site-packages/flask/app.py", line 1821, in handle_user_exception
    reraise(exc_type, exc_value, tb)
  File "/home/leeolivier/.local/lib/python3.8/site-packages/flask/_compat.py", line 39, in reraise
    raise value
  File "/home/leeolivier/.local/lib/python3.8/site-packages/flask/app.py", line 1950, in full_dispatch_request
    rv = self.dispatch_request()
  File "/home/leeolivier/.local/lib/python3.8/site-packages/flask/app.py", line 1936, in dispatch_request
    return self.view_functions[rule.endpoint](**req.view_args)
  File "/home/leeolivier/.local/lib/python3.8/site-packages/flask_login/utils.py", line 272, in decorated_view
    return func(*args, **kwargs)
  File "/home/leeolivier/bitcube/venv/app/routes.py", line 122, in user
    name = User.query.filter_by(name=name).first_or_404()
UnboundLocalError: local variable 'name' referenced before assignment
2020-08-14 11:48:21,139 INFO: bitcube startup [in /home/leeolivier/bitcube/venv/app/__init__.py:47]
2020-08-14 11:48:25,325 ERROR: Exception on /user/bruce [GET] [in /home/leeolivier/.local/lib/python3.8/site-packages/flask/app.py:1891]
Traceback (most recent call last):
  File "/home/leeolivier/.local/lib/python3.8/site-packages/flask/app.py", line 2447, in wsgi_app
    response = self.full_dispatch_request()
  File "/home/leeolivier/.local/lib/python3.8/site-packages/flask/app.py", line 1952, in full_dispatch_request
    rv = self.handle_user_exception(e)
  File "/home/leeolivier/.local/lib/python3.8/site-packages/flask/app.py", line 1821, in handle_user_exception
    reraise(exc_type, exc_value, tb)
  File "/home/leeolivier/.local/lib/python3.8/site-packages/flask/_compat.py", line 39, in reraise
    raise value
  File "/home/leeolivier/.local/lib/python3.8/site-packages/flask/app.py", line 1950, in full_dispatch_request
    rv = self.dispatch_request()
  File "/home/leeolivier/.local/lib/python3.8/site-packages/flask/app.py", line 1936, in dispatch_request
    return self.view_functions[rule.endpoint](**req.view_args)
  File "/home/leeolivier/.local/lib/python3.8/site-packages/flask_login/utils.py", line 272, in decorated_view
    return func(*args, **kwargs)
  File "/home/leeolivier/bitcube/venv/app/routes.py", line 122, in user
    name = User.query.filter_by(name=name)
UnboundLocalError: local variable 'name' referenced before assignment
2020-08-14 11:48:26,764 ERROR: Exception on /user/bruce [GET] [in /home/leeolivier/.local/lib/python3.8/site-packages/flask/app.py:1891]
Traceback (most recent call last):
  File "/home/leeolivier/.local/lib/python3.8/site-packages/flask/app.py", line 2447, in wsgi_app
    response = self.full_dispatch_request()
  File "/home/leeolivier/.local/lib/python3.8/site-packages/flask/app.py", line 1952, in full_dispatch_request
    rv = self.handle_user_exception(e)
  File "/home/leeolivier/.local/lib/python3.8/site-packages/flask/app.py", line 1821, in handle_user_exception
    reraise(exc_type, exc_value, tb)
  File "/home/leeolivier/.local/lib/python3.8/site-packages/flask/_compat.py", line 39, in reraise
    raise value
  File "/home/leeolivier/.local/lib/python3.8/site-packages/flask/app.py", line 1950, in full_dispatch_request
    rv = self.dispatch_request()
  File "/home/leeolivier/.local/lib/python3.8/site-packages/flask/app.py", line 1936, in dispatch_request
    return self.view_functions[rule.endpoint](**req.view_args)
  File "/home/leeolivier/.local/lib/python3.8/site-packages/flask_login/utils.py", line 272, in decorated_view
    return func(*args, **kwargs)
  File "/home/leeolivier/bitcube/venv/app/routes.py", line 122, in user
    name = User.query.filter_by(name=name)
UnboundLocalError: local variable 'name' referenced before assignment
2020-08-14 11:48:26,986 ERROR: Exception on /user/bruce [GET] [in /home/leeolivier/.local/lib/python3.8/site-packages/flask/app.py:1891]
Traceback (most recent call last):
  File "/home/leeolivier/.local/lib/python3.8/site-packages/flask/app.py", line 2447, in wsgi_app
    response = self.full_dispatch_request()
  File "/home/leeolivier/.local/lib/python3.8/site-packages/flask/app.py", line 1952, in full_dispatch_request
    rv = self.handle_user_exception(e)
  File "/home/leeolivier/.local/lib/python3.8/site-packages/flask/app.py", line 1821, in handle_user_exception
    reraise(exc_type, exc_value, tb)
  File "/home/leeolivier/.local/lib/python3.8/site-packages/flask/_compat.py", line 39, in reraise
    raise value
  File "/home/leeolivier/.local/lib/python3.8/site-packages/flask/app.py", line 1950, in full_dispatch_request
    rv = self.dispatch_request()
  File "/home/leeolivier/.local/lib/python3.8/site-packages/flask/app.py", line 1936, in dispatch_request
    return self.view_functions[rule.endpoint](**req.view_args)
  File "/home/leeolivier/.local/lib/python3.8/site-packages/flask_login/utils.py", line 272, in decorated_view
    return func(*args, **kwargs)
  File "/home/leeolivier/bitcube/venv/app/routes.py", line 122, in user
    name = User.query.filter_by(name=name)
UnboundLocalError: local variable 'name' referenced before assignment
2020-08-14 11:48:27,132 ERROR: Exception on /user/bruce [GET] [in /home/leeolivier/.local/lib/python3.8/site-packages/flask/app.py:1891]
Traceback (most recent call last):
  File "/home/leeolivier/.local/lib/python3.8/site-packages/flask/app.py", line 2447, in wsgi_app
    response = self.full_dispatch_request()
  File "/home/leeolivier/.local/lib/python3.8/site-packages/flask/app.py", line 1952, in full_dispatch_request
    rv = self.handle_user_exception(e)
  File "/home/leeolivier/.local/lib/python3.8/site-packages/flask/app.py", line 1821, in handle_user_exception
    reraise(exc_type, exc_value, tb)
  File "/home/leeolivier/.local/lib/python3.8/site-packages/flask/_compat.py", line 39, in reraise
    raise value
  File "/home/leeolivier/.local/lib/python3.8/site-packages/flask/app.py", line 1950, in full_dispatch_request
    rv = self.dispatch_request()
  File "/home/leeolivier/.local/lib/python3.8/site-packages/flask/app.py", line 1936, in dispatch_request
    return self.view_functions[rule.endpoint](**req.view_args)
  File "/home/leeolivier/.local/lib/python3.8/site-packages/flask_login/utils.py", line 272, in decorated_view
    return func(*args, **kwargs)
  File "/home/leeolivier/bitcube/venv/app/routes.py", line 122, in user
    name = User.query.filter_by(name=name)
UnboundLocalError: local variable 'name' referenced before assignment
2020-08-14 11:48:27,257 ERROR: Exception on /user/bruce [GET] [in /home/leeolivier/.local/lib/python3.8/site-packages/flask/app.py:1891]
Traceback (most recent call last):
  File "/home/leeolivier/.local/lib/python3.8/site-packages/flask/app.py", line 2447, in wsgi_app
    response = self.full_dispatch_request()
  File "/home/leeolivier/.local/lib/python3.8/site-packages/flask/app.py", line 1952, in full_dispatch_request
    rv = self.handle_user_exception(e)
  File "/home/leeolivier/.local/lib/python3.8/site-packages/flask/app.py", line 1821, in handle_user_exception
    reraise(exc_type, exc_value, tb)
  File "/home/leeolivier/.local/lib/python3.8/site-packages/flask/_compat.py", line 39, in reraise
    raise value
  File "/home/leeolivier/.local/lib/python3.8/site-packages/flask/app.py", line 1950, in full_dispatch_request
    rv = self.dispatch_request()
  File "/home/leeolivier/.local/lib/python3.8/site-packages/flask/app.py", line 1936, in dispatch_request
    return self.view_functions[rule.endpoint](**req.view_args)
  File "/home/leeolivier/.local/lib/python3.8/site-packages/flask_login/utils.py", line 272, in decorated_view
    return func(*args, **kwargs)
  File "/home/leeolivier/bitcube/venv/app/routes.py", line 122, in user
    name = User.query.filter_by(name=name)
UnboundLocalError: local variable 'name' referenced before assignment
2020-08-14 11:53:28,293 INFO: bitcube startup [in /home/leeolivier/bitcube/venv/app/__init__.py:47]
2020-08-14 11:54:05,114 INFO: bitcube startup [in /home/leeolivier/bitcube/venv/app/__init__.py:47]
